2021-12-18 18:04:31,284 INFO    Thread-972:3400 [wandb_setup.py:_flush():69] setting env: {'root_dir': 'W:\\shared\\python\\gymrl', 'sweep_id': 'i91zir54', 'project': 'my-test-project', 'run_id': 'xd57pykp', 'sweep_param_path': 'W:\\shared\\python\\gymrl\\wandb\\sweep-i91zir54\\config-xd57pykp.yaml'}
2021-12-18 18:04:31,285 INFO    Thread-972:3400 [wandb_setup.py:_flush():69] setting login settings: {}
2021-12-18 18:04:31,285 INFO    Thread-972:3400 [wandb_init.py:_log_setup():334] Logging user logs to W:\shared\python\gymrl\wandb\run-20211218_180431-xd57pykp\logs\debug.log
2021-12-18 18:04:31,285 INFO    Thread-972:3400 [wandb_init.py:_log_setup():335] Logging internal logs to W:\shared\python\gymrl\wandb\run-20211218_180431-xd57pykp\logs\debug-internal.log
2021-12-18 18:04:31,285 INFO    Thread-972:3400 [wandb_init.py:_jupyter_setup():285] configuring jupyter hooks <wandb.sdk.wandb_init._WandbInit object at 0x0000028E16DD5880>
2021-12-18 18:04:31,286 INFO    Thread-972:3400 [wandb_init.py:init():367] calling init triggers
2021-12-18 18:04:31,286 INFO    Thread-972:3400 [wandb_init.py:init():372] wandb.init called with sweep_config: {'dropout': 0, 'epochs': 5, 'fp_emax': 46, 'fp_explim': 'CPFLOAT_EXPRANGE_TARG', 'fp_flip': 'CPFLOAT_NO_SOFTERR', 'fp_p': 0.4448667229699565, 'fp_precision': 15, 'fp_round': 'CPFLOAT_RND_NA', 'fp_subnormal': 'CPFLOAT_SUBN_USE', 'layer_sizes': [784, 30, 10], 'learning_rate': 0.1, 'loss': 'mean_squared_error', 'minibatch_size': 10, 'momentum_coefficient': 0, 'weight_decay': 0.0001}
config: {}
2021-12-18 18:04:31,286 INFO    Thread-972:3400 [wandb_init.py:init():416] starting backend
2021-12-18 18:04:31,286 INFO    Thread-972:3400 [backend.py:_multiprocessing_setup():69] multiprocessing start_methods=spawn, using: spawn
2021-12-18 18:04:31,288 INFO    Thread-972:3400 [backend.py:ensure_launched():123] starting backend process...
2021-12-18 18:04:31,353 INFO    Thread-972:3400 [backend.py:ensure_launched():127] started backend process with pid: 23312
2021-12-18 18:04:31,353 INFO    Thread-972:3400 [wandb_init.py:init():421] backend started and connected
2021-12-18 18:04:31,362 INFO    Thread-972:3400 [wandb_run.py:_config_callback():733] config_cb None None {'dropout': 0, 'epochs': 5, 'fp_emax': 46, 'fp_explim': 'CPFLOAT_EXPRANGE_TARG', 'fp_flip': 'CPFLOAT_NO_SOFTERR', 'fp_p': 0.4448667229699565, 'fp_precision': 15, 'fp_round': 'CPFLOAT_RND_NA', 'fp_subnormal': 'CPFLOAT_SUBN_USE', 'layer_sizes': [784, 30, 10], 'learning_rate': 0.1, 'loss': 'mean_squared_error', 'minibatch_size': 10, 'momentum_coefficient': 0, 'weight_decay': 0.0001}
2021-12-18 18:04:31,362 INFO    Thread-972:3400 [wandb_init.py:init():461] updated telemetry
2021-12-18 18:04:31,363 INFO    Thread-972:3400 [wandb_init.py:init():480] communicating current version
2021-12-18 18:04:32,306 INFO    Thread-972:3400 [wandb_init.py:init():485] got version response upgrade_message: "wandb version 0.12.9 is available!  To upgrade, please run:\n $ pip install wandb --upgrade"

2021-12-18 18:04:32,307 INFO    Thread-972:3400 [wandb_init.py:init():493] communicating run to backend with 30 second timeout
2021-12-18 18:04:32,659 INFO    Thread-972:3400 [wandb_init.py:init():518] starting run threads in backend
2021-12-18 18:04:32,831 INFO    Thread-972:3400 [wandb_run.py:_console_start():1476] atexit reg
2021-12-18 18:04:32,831 INFO    Thread-972:3400 [wandb_run.py:_redirect():1339] redirect: SettingsConsole.WRAP
2021-12-18 18:04:32,831 INFO    Thread-972:3400 [wandb_run.py:_redirect():1374] Wrapping output streams.
2021-12-18 18:04:32,831 INFO    Thread-972:3400 [wandb_run.py:_redirect():1390] Redirects installed.
2021-12-18 18:04:32,832 INFO    Thread-972:3400 [wandb_init.py:init():542] run started, returning control to user process
2021-12-18 18:07:58,933 ERROR   Thread-11 :3400 [retry.py:__call__():111] Retry attempt failed:
Traceback (most recent call last):
  File "c:\users\lubko\appdata\local\programs\python\python39\lib\site-packages\urllib3\connectionpool.py", line 699, in urlopen
    httplib_response = self._make_request(
  File "c:\users\lubko\appdata\local\programs\python\python39\lib\site-packages\urllib3\connectionpool.py", line 394, in _make_request
    conn.request(method, url, **httplib_request_kw)
  File "c:\users\lubko\appdata\local\programs\python\python39\lib\site-packages\urllib3\connection.py", line 234, in request
    super(HTTPConnection, self).request(method, url, body=body, headers=headers)
  File "c:\users\lubko\appdata\local\programs\python\python39\lib\http\client.py", line 1255, in request
    self._send_request(method, url, body, headers, encode_chunked)
  File "c:\users\lubko\appdata\local\programs\python\python39\lib\http\client.py", line 1301, in _send_request
    self.endheaders(body, encode_chunked=encode_chunked)
  File "c:\users\lubko\appdata\local\programs\python\python39\lib\http\client.py", line 1250, in endheaders
    self._send_output(message_body, encode_chunked=encode_chunked)
  File "c:\users\lubko\appdata\local\programs\python\python39\lib\http\client.py", line 1010, in _send_output
    self.send(msg)
  File "c:\users\lubko\appdata\local\programs\python\python39\lib\http\client.py", line 971, in send
    self.sock.sendall(data)
  File "c:\users\lubko\appdata\local\programs\python\python39\lib\ssl.py", line 1204, in sendall
    v = self.send(byte_view[count:])
  File "c:\users\lubko\appdata\local\programs\python\python39\lib\ssl.py", line 1173, in send
    return self._sslobj.write(data)
ConnectionAbortedError: [WinError 10053] An established connection was aborted by the software in your host machine

During handling of the above exception, another exception occurred:

Traceback (most recent call last):
  File "c:\users\lubko\appdata\local\programs\python\python39\lib\site-packages\requests\adapters.py", line 439, in send
    resp = conn.urlopen(
  File "c:\users\lubko\appdata\local\programs\python\python39\lib\site-packages\urllib3\connectionpool.py", line 755, in urlopen
    retries = retries.increment(
  File "c:\users\lubko\appdata\local\programs\python\python39\lib\site-packages\urllib3\util\retry.py", line 531, in increment
    raise six.reraise(type(error), error, _stacktrace)
  File "c:\users\lubko\appdata\local\programs\python\python39\lib\site-packages\urllib3\packages\six.py", line 734, in reraise
    raise value.with_traceback(tb)
  File "c:\users\lubko\appdata\local\programs\python\python39\lib\site-packages\urllib3\connectionpool.py", line 699, in urlopen
    httplib_response = self._make_request(
  File "c:\users\lubko\appdata\local\programs\python\python39\lib\site-packages\urllib3\connectionpool.py", line 394, in _make_request
    conn.request(method, url, **httplib_request_kw)
  File "c:\users\lubko\appdata\local\programs\python\python39\lib\site-packages\urllib3\connection.py", line 234, in request
    super(HTTPConnection, self).request(method, url, body=body, headers=headers)
  File "c:\users\lubko\appdata\local\programs\python\python39\lib\http\client.py", line 1255, in request
    self._send_request(method, url, body, headers, encode_chunked)
  File "c:\users\lubko\appdata\local\programs\python\python39\lib\http\client.py", line 1301, in _send_request
    self.endheaders(body, encode_chunked=encode_chunked)
  File "c:\users\lubko\appdata\local\programs\python\python39\lib\http\client.py", line 1250, in endheaders
    self._send_output(message_body, encode_chunked=encode_chunked)
  File "c:\users\lubko\appdata\local\programs\python\python39\lib\http\client.py", line 1010, in _send_output
    self.send(msg)
  File "c:\users\lubko\appdata\local\programs\python\python39\lib\http\client.py", line 971, in send
    self.sock.sendall(data)
  File "c:\users\lubko\appdata\local\programs\python\python39\lib\ssl.py", line 1204, in sendall
    v = self.send(byte_view[count:])
  File "c:\users\lubko\appdata\local\programs\python\python39\lib\ssl.py", line 1173, in send
    return self._sslobj.write(data)
urllib3.exceptions.ProtocolError: ('Connection aborted.', ConnectionAbortedError(10053, 'An established connection was aborted by the software in your host machine', None, 10053, None))

During handling of the above exception, another exception occurred:

Traceback (most recent call last):
  File "c:\users\lubko\appdata\local\programs\python\python39\lib\site-packages\wandb\old\retry.py", line 96, in __call__
    result = self._call_fn(*args, **kwargs)
  File "c:\users\lubko\appdata\local\programs\python\python39\lib\site-packages\wandb\sdk\internal\internal_api.py", line 123, in execute
    return self.client.execute(*args, **kwargs)
  File "c:\users\lubko\appdata\local\programs\python\python39\lib\site-packages\wandb\vendor\gql-0.2.0\gql\client.py", line 52, in execute
    result = self._get_result(document, *args, **kwargs)
  File "c:\users\lubko\appdata\local\programs\python\python39\lib\site-packages\wandb\vendor\gql-0.2.0\gql\client.py", line 60, in _get_result
    return self.transport.execute(document, *args, **kwargs)
  File "c:\users\lubko\appdata\local\programs\python\python39\lib\site-packages\wandb\vendor\gql-0.2.0\gql\transport\requests.py", line 38, in execute
    request = requests.post(self.url, **post_args)
  File "c:\users\lubko\appdata\local\programs\python\python39\lib\site-packages\requests\api.py", line 119, in post
    return request('post', url, data=data, json=json, **kwargs)
  File "c:\users\lubko\appdata\local\programs\python\python39\lib\site-packages\requests\api.py", line 61, in request
    return session.request(method=method, url=url, **kwargs)
  File "c:\users\lubko\appdata\local\programs\python\python39\lib\site-packages\requests\sessions.py", line 542, in request
    resp = self.send(prep, **send_kwargs)
  File "c:\users\lubko\appdata\local\programs\python\python39\lib\site-packages\requests\sessions.py", line 655, in send
    r = adapter.send(request, **kwargs)
  File "c:\users\lubko\appdata\local\programs\python\python39\lib\site-packages\requests\adapters.py", line 498, in send
    raise ConnectionError(err, request=request)
requests.exceptions.ConnectionError: ('Connection aborted.', ConnectionAbortedError(10053, 'An established connection was aborted by the software in your host machine', None, 10053, None))
2021-12-18 18:09:41,646 INFO    Thread-972:3400 [wandb_run.py:finish():1135] finishing run lubomirkurcak/my-test-project/xd57pykp
