2022-03-01 23:28:31,212 INFO    Thread-20 :7508 [wandb_setup.py:_flush():69] setting env: {'project': 'my-test-project', 'entity': 'lubomirkurcak', 'root_dir': 'W:\\rpnn\\python', 'sweep_id': 'fc3gl8vd', 'run_id': '1dxp7e5g', 'sweep_param_path': 'W:\\rpnn\\python\\wandb\\sweep-fc3gl8vd\\config-1dxp7e5g.yaml'}
2022-03-01 23:28:31,212 INFO    Thread-20 :7508 [wandb_setup.py:_flush():69] setting login settings: {}
2022-03-01 23:28:31,212 INFO    Thread-20 :7508 [wandb_init.py:_log_setup():334] Logging user logs to W:\rpnn\python\wandb\run-20220301_232831-1dxp7e5g\logs\debug.log
2022-03-01 23:28:31,212 INFO    Thread-20 :7508 [wandb_init.py:_log_setup():335] Logging internal logs to W:\rpnn\python\wandb\run-20220301_232831-1dxp7e5g\logs\debug-internal.log
2022-03-01 23:28:31,213 INFO    Thread-20 :7508 [wandb_init.py:_jupyter_setup():285] configuring jupyter hooks <wandb.sdk.wandb_init._WandbInit object at 0x0000015CA8A3C3A0>
2022-03-01 23:28:31,213 INFO    Thread-20 :7508 [wandb_init.py:init():367] calling init triggers
2022-03-01 23:28:31,213 INFO    Thread-20 :7508 [wandb_init.py:init():372] wandb.init called with sweep_config: {'dropout': 0, 'epochs': 5, 'fp_emax': 6, 'fp_explim': 'CPFLOAT_EXPRANGE_STOR', 'fp_flip': 'CPFLOAT_SOFTERR', 'fp_p': 0.0404399079158948, 'fp_precision': 19, 'fp_round': 'CPFLOAT_RND_TN', 'fp_subnormal': 'CPFLOAT_SUBN_RND', 'layer_sizes': [784, 30, 10], 'learning_rate': 0.1, 'loss': 'mean_squared_error', 'minibatch_size': 10, 'momentum_coefficient': 0, 'weight_decay': 0.0001}
config: {}
2022-03-01 23:28:31,213 INFO    Thread-20 :7508 [wandb_init.py:init():416] starting backend
2022-03-01 23:28:31,213 INFO    Thread-20 :7508 [backend.py:_multiprocessing_setup():69] multiprocessing start_methods=spawn, using: spawn
2022-03-01 23:28:31,215 INFO    Thread-20 :7508 [backend.py:ensure_launched():123] starting backend process...
2022-03-01 23:28:31,278 INFO    Thread-20 :7508 [backend.py:ensure_launched():127] started backend process with pid: 15132
2022-03-01 23:28:31,279 INFO    Thread-20 :7508 [wandb_init.py:init():421] backend started and connected
2022-03-01 23:28:31,290 INFO    Thread-20 :7508 [wandb_run.py:_config_callback():733] config_cb None None {'dropout': 0, 'epochs': 5, 'fp_emax': 6, 'fp_explim': 'CPFLOAT_EXPRANGE_STOR', 'fp_flip': 'CPFLOAT_SOFTERR', 'fp_p': 0.0404399079158948, 'fp_precision': 19, 'fp_round': 'CPFLOAT_RND_TN', 'fp_subnormal': 'CPFLOAT_SUBN_RND', 'layer_sizes': [784, 30, 10], 'learning_rate': 0.1, 'loss': 'mean_squared_error', 'minibatch_size': 10, 'momentum_coefficient': 0, 'weight_decay': 0.0001}
2022-03-01 23:28:31,290 INFO    Thread-20 :7508 [wandb_init.py:init():461] updated telemetry
2022-03-01 23:28:31,292 INFO    Thread-20 :7508 [wandb_init.py:init():480] communicating current version
2022-03-01 23:28:32,200 INFO    Thread-20 :7508 [wandb_init.py:init():485] got version response upgrade_message: "wandb version 0.12.11 is available!  To upgrade, please run:\n $ pip install wandb --upgrade"

2022-03-01 23:28:32,201 INFO    Thread-20 :7508 [wandb_init.py:init():493] communicating run to backend with 30 second timeout
2022-03-01 23:28:32,551 INFO    Thread-20 :7508 [wandb_init.py:init():518] starting run threads in backend
2022-03-01 23:28:32,713 INFO    Thread-20 :7508 [wandb_run.py:_console_start():1476] atexit reg
2022-03-01 23:28:32,714 INFO    Thread-20 :7508 [wandb_run.py:_redirect():1339] redirect: SettingsConsole.WRAP
2022-03-01 23:28:32,714 INFO    Thread-20 :7508 [wandb_run.py:_redirect():1374] Wrapping output streams.
2022-03-01 23:28:32,714 INFO    Thread-20 :7508 [wandb_run.py:_redirect():1390] Redirects installed.
2022-03-01 23:28:32,714 INFO    Thread-20 :7508 [wandb_init.py:init():542] run started, returning control to user process
2022-03-01 23:35:23,001 ERROR   Thread-11 :7508 [retry.py:__call__():111] Retry attempt failed:
Traceback (most recent call last):
  File "c:\users\lubko\appdata\local\programs\python\python39\lib\site-packages\urllib3\connectionpool.py", line 699, in urlopen
    httplib_response = self._make_request(
  File "c:\users\lubko\appdata\local\programs\python\python39\lib\site-packages\urllib3\connectionpool.py", line 382, in _make_request
    self._validate_conn(conn)
  File "c:\users\lubko\appdata\local\programs\python\python39\lib\site-packages\urllib3\connectionpool.py", line 1010, in _validate_conn
    conn.connect()
  File "c:\users\lubko\appdata\local\programs\python\python39\lib\site-packages\urllib3\connection.py", line 411, in connect
    self.sock = ssl_wrap_socket(
  File "c:\users\lubko\appdata\local\programs\python\python39\lib\site-packages\urllib3\util\ssl_.py", line 428, in ssl_wrap_socket
    ssl_sock = _ssl_wrap_socket_impl(
  File "c:\users\lubko\appdata\local\programs\python\python39\lib\site-packages\urllib3\util\ssl_.py", line 472, in _ssl_wrap_socket_impl
    return ssl_context.wrap_socket(sock, server_hostname=server_hostname)
  File "c:\users\lubko\appdata\local\programs\python\python39\lib\ssl.py", line 500, in wrap_socket
    return self.sslsocket_class._create(
  File "c:\users\lubko\appdata\local\programs\python\python39\lib\ssl.py", line 1040, in _create
    self.do_handshake()
  File "c:\users\lubko\appdata\local\programs\python\python39\lib\ssl.py", line 1309, in do_handshake
    self._sslobj.do_handshake()
ssl.SSLEOFError: EOF occurred in violation of protocol (_ssl.c:1123)

During handling of the above exception, another exception occurred:

Traceback (most recent call last):
  File "c:\users\lubko\appdata\local\programs\python\python39\lib\site-packages\requests\adapters.py", line 439, in send
    resp = conn.urlopen(
  File "c:\users\lubko\appdata\local\programs\python\python39\lib\site-packages\urllib3\connectionpool.py", line 755, in urlopen
    retries = retries.increment(
  File "c:\users\lubko\appdata\local\programs\python\python39\lib\site-packages\urllib3\util\retry.py", line 573, in increment
    raise MaxRetryError(_pool, url, error or ResponseError(cause))
urllib3.exceptions.MaxRetryError: HTTPSConnectionPool(host='api.wandb.ai', port=443): Max retries exceeded with url: /graphql (Caused by SSLError(SSLEOFError(8, 'EOF occurred in violation of protocol (_ssl.c:1123)')))

During handling of the above exception, another exception occurred:

Traceback (most recent call last):
  File "c:\users\lubko\appdata\local\programs\python\python39\lib\site-packages\wandb\old\retry.py", line 96, in __call__
    result = self._call_fn(*args, **kwargs)
  File "c:\users\lubko\appdata\local\programs\python\python39\lib\site-packages\wandb\sdk\internal\internal_api.py", line 123, in execute
    return self.client.execute(*args, **kwargs)
  File "c:\users\lubko\appdata\local\programs\python\python39\lib\site-packages\wandb\vendor\gql-0.2.0\gql\client.py", line 52, in execute
    result = self._get_result(document, *args, **kwargs)
  File "c:\users\lubko\appdata\local\programs\python\python39\lib\site-packages\wandb\vendor\gql-0.2.0\gql\client.py", line 60, in _get_result
    return self.transport.execute(document, *args, **kwargs)
  File "c:\users\lubko\appdata\local\programs\python\python39\lib\site-packages\wandb\vendor\gql-0.2.0\gql\transport\requests.py", line 38, in execute
    request = requests.post(self.url, **post_args)
  File "c:\users\lubko\appdata\local\programs\python\python39\lib\site-packages\requests\api.py", line 119, in post
    return request('post', url, data=data, json=json, **kwargs)
  File "c:\users\lubko\appdata\local\programs\python\python39\lib\site-packages\requests\api.py", line 61, in request
    return session.request(method=method, url=url, **kwargs)
  File "c:\users\lubko\appdata\local\programs\python\python39\lib\site-packages\requests\sessions.py", line 542, in request
    resp = self.send(prep, **send_kwargs)
  File "c:\users\lubko\appdata\local\programs\python\python39\lib\site-packages\requests\sessions.py", line 655, in send
    r = adapter.send(request, **kwargs)
  File "c:\users\lubko\appdata\local\programs\python\python39\lib\site-packages\requests\adapters.py", line 514, in send
    raise SSLError(e, request=request)
requests.exceptions.SSLError: HTTPSConnectionPool(host='api.wandb.ai', port=443): Max retries exceeded with url: /graphql (Caused by SSLError(SSLEOFError(8, 'EOF occurred in violation of protocol (_ssl.c:1123)')))
2022-03-01 23:39:56,710 INFO    Thread-20 :7508 [wandb_run.py:finish():1135] finishing run lubomirkurcak/my-test-project/1dxp7e5g
